

# 文件和异常



## 写文件
我们使用 open 函数的写入模式来写文件：


```python 
f = open('test.txt', 'w')
f.write('hello world.')
f.close()
```


```python 
print(open('test.txt').read())
```


使用 w 模式时，如果文件不存在会被创建

除了写入模式，还有追加模式 a



读写模式w+


```python 
f = open('test.txt', 'w+')
f.write('hello world. morning.')
f.seek(3)
print(f.read())  # hello world.
f.close()
```



## 读文件
使用 open 函数 来读文件，使用文件名的字符串作为输入参数：

默认打开文件是 ‘r’ 读模式


```python 
f = open("test.txt")

# 默认以读的方式打开文件，如果文件不存在会报错。
# 可以使用 read 方法来读入文件中的所有内容：
text = f.read()
print(text)
```


按照行读入内容，readlines 方法返回一个列表，每个元素代表文件中每一行的内容：


```python 
f = open("test.txt")
lines = f.readlines()
print(lines)
f.close()
```


```python 
# 事实上，我们可以将 f 放在一个循环中，得到它每一行的内容：
f = open('test.txt')
for line in f:
    print(line)
f.close()
```


### 上下文管理器


```python 
with open('my_file.txt', 'w') as fp:
    data = fp.write("Hello world")
```


这等效于下面的代码，但是要更简便：


```python 
fp = open('my_file.txt', 'w')
try:
    # do stuff with f
    data = fp.write("Hello world")
finally:
    fp.close()
```


## 自定义上下文管理器
比如可以这样定义一个简单的上下文管理器：


```python 
class ContextManager(object):
    def __enter__(self):
        print("Entering")

    def __exit__(self, exc_type, exc_value, traceback):
        print("Exiting")


with ContextManager():
    print("inside operate")
```


### __enter__ 的返回值
如果在 __enter__ 方法下添加了返回值，

那么我们可以使用 as 把这个返回值传给某个参数：


```python 
class ContextManager2(object):
    def __enter__(self):
        print("Entering")
        return "my value"

    def __exit__(self, exc_type, exc_value, traceback):
        print("Exiting")


with ContextManager2() as val:
    print(val)

```


一个通常的做法是将 __enter__ 的返回值设为这个上下文管理器对象本身，
文件对象就是这样做的.


```python 
class ContextManager3(object):
    def __enter__(self):
        print("Entering")
        return self

    def __exit__(self, exc_type, exc_value, traceback):
        print("Exiting")

```


### 错误处理
上下文管理器对象将错误处理交给 __exit__ 进行，可以将错误类型，
错误值和 traceback 等内容作为参数传递给 __exit__ 函数：


```python 
class ContextManager4(object):
    def __enter__(self):
        print("Entering")

    def __exit__(self, exc_type, exc_value, traceback):
        print("Exiting")
        if exc_type is not None:
            print("  Exception:", exc_value)
            return True  # 不想让错误抛出，只需要将 __exit__ 的返回值设为 True


with ContextManager4():
    print(1 / 0)

```


```python 
import os
os.remove('my_file.txt')
```


## 二进制文件

二进制读写模式 b：


```python 
import os

f = open('binary.bin', 'wb')
f.write(os.urandom(10))
f.close()
```


```python 
f = open('binary.bin', 'rb')
print(repr(f.read()))
f.close()
```


## with 方法
事实上，Python提供了更安全的方法，当 with 块的内容结束后，
Python会自动调用它的close 方法，确保读写的安全：


```python 
with open('new_file.txt', 'w') as f:
    for i in range(3000):
        x = 1.0 / (i - 1000)
        f.write('hello world: ' + str(i) + '\n')
```


与 try/exception/finally 效果相同，但更简单。

查看文件写的结果，虽然触发error，但已经写的内容是成功的。


```python 
!tail new_file.txt
```


```python 
!wc -l new_file.txt
```


```python 
# 删除文件：
import os
os.remove('test.txt')
os.remove('binary.bin')
os.remove('new_file.txt')
```


# 异常

## try & except 块

捕捉不同的错误类型，尝试在下面输入框输入：-1，1，2，q


```python 
import math

while True:
    try:
        text = input('>')
        if text[0] == 'q':
            break
        x = float(text)
        y = 1 / math.log10(x)
        print("1/log10({0}) = {1}".format(x, y))
    except ValueError:
        print("value must bigger than 0")
    except ZeroDivisionError:
        print("the value must not be 1")

```


## 自定义异常
异常是标准库中的类，这意味着我们可以自定义异常类：

尝试在文本输入框输入：k，start，q


```python 
class CommandError(ValueError):
    print("bad command operation. must input 'start', 'stop', 'pause'")
    


valid_commands = {'start', 'stop', 'pause'}
while True:
    command = input('>')
    if command == 'q':
        break
    try:
        if command.lower() not in valid_commands:
            raise CommandError('Invalid command: %s' % command)
        print('input command:', command)
    except CommandError:
        print("bad command string: %s" % command)

```


## finally
try/catch 块还有一个可选的关键词 finally。

不管 try 块有没有异常， finally 块的内容总是会被执行，
而且会在抛出异常前执行，因此可以用来作为安全保证，

比如文件操作时，常在finally关闭文件。


```python 
try:
    print(1 / 0)
except ZeroDivisionError:
    print('divide by 0.')
finally:
    print('finally was called.')
```

